Workbook

Sheet 1 sleep
A1: study_word | B1: thisN | C1: thisTrialN | D1: thisRepN | E1: StudySlider.response | F1: StudySlider.rt | G1: test_word | H1: Reference | I1: old_new | J1: test_textbox.text | K1: testmouse.x | L1: testmouse.y | M1: testmouse.leftButton | N1: testmouse.midButton | O1: testmouse.rightButton | P1: testmouse.time | Q1: testmouse.clicked_name | R1: trials.thisRepN | S1: trials.thisTrialN | T1: trials.thisN | U1: trials.thisIndex | V1: trials_2.thisRepN | W1: trials_2.thisTrialN | X1: trials_2.thisN | Y1: trials_2.thisIndex | Z1: thisRow.t | AA1: notes | AB1: trial.started | AC1: StudyText.started | AD1: StudySlider.started | AE1: trial.stopped | AF1: trials.StudySlider.response | AG1: trials.StudySlider.rt | AH1: Test_Phase.started | AI1: TestText.started | AJ1: test_textbox.started | AK1: submit_text.started | AL1: testmouse.started | AM1: Test_Phase.stopped | AN1: trials_2.test_textbox.text | AO1: trials_2.testmouse.x | AP1: trials_2.testmouse.y | AQ1: trials_2.testmouse.leftButton | AR1: trials_2.testmouse.midButton | AS1: trials_2.testmouse.rightButton | AT1: trials_2.testmouse.time | AU1: trials_2.testmouse.clicked_name | AV1: TestText.stopped | AW1: test_textbox.stopped | AX1: submit_text.stopped | AY1: testmouse.stopped | AZ1: participant | BA1: session | BB1: date | BC1: expName | BD1: expVersion | BE1: psychopyVersion | BF1: frameRate | BG1: expStart
A2: audacious | B2: 0 | C2: 0 | D2: 0 | E2: 1 | F2: 3.1349707 | R2: 0 | S2: 0 | T2: 0 | U2: 12 | Z2: 0.040640541 | AB2: 0.027080375 | AC2: 0.040640541 | AD2: 0.040640541 | AE2: 3.1704876 | AF2: 1 | AG2: 3.1349707 | AZ2: 1 | BA2: 1 | BB2: 2025-11-08_23h53.41.348 | BC2: word_priming_sp | BE2: 2025.1.1 | BF2: 120.77161 | BG2: 2025-11-08 23h53.47.999473 +0530
A3: parsimony | B3: 1 | C3: 1 | D3: 0 | E3: 4.971223 | F3: 2.0872392 | R3: 0 | S3: 1 | T3: 1 | U3: 18 | Z3: 3.180851 | AB3: 3.1742484 | AC3: 3.180851 | AD3: 3.180851 | AE3: 5.2705326 | AF3: 4.971223 | AG3: 2.0872392 | AZ3: 1 | BA3: 1 | BB3: 2025-11-08_23h53.41.348 | BC3: word_priming_sp | BE3: 2025.1.1 | BF3: 120.77161 | BG3: 2025-11-08 23h53.47.999473 +0530
A4: parlance | B4: 2 | C4: 2 | D4: 0 | E4: 5 | F4: 2.4386932 | R4: 0 | S4: 2 | T4: 2 | U4: 11 | Z4: 5.2799035 | AB4: 5.2733377 | AC4: 5.2799035 | AD4: 5.2799035 | AE4: 7.7208772 | AF4: 5 | AG4: 2.4386932 | AZ4: 1 | BA4: 1 | BB4: 2025-11-08_23h53.41.348 | BC4: word_priming_sp | BE4: 2025.1.1 | BF4: 120.77161 | BG4: 2025-11-08 23h53.47.999473 +0530
A5: carpet | B5: 3 | C5: 3 | D5: 0 | E5: 1.0395683 | F5: 2.3388095 | R5: 0 | S5: 3 | T5: 3 | U5: 1 | Z5: 7.7292315 | AB5: 7.7226922 | AC5: 7.7292315 | AD5: 7.7292315 | AE5: 10.070828 | AF5: 1.0395683 | AG5: 2.3388095 | AZ5: 1 | BA5: 1 | BB5: 2025-11-08_23h53.41.348 | BC5: word_priming_sp | BE5: 2025.1.1 | BF5: 120.77161 | BG5: 2025-11-08 23h53.47.999473 +0530
A6: cacophony | B6: 4 | C6: 4 | D6: 0 | E6: 1.0395683 | F6: 1.2714197 | R6: 0 | S6: 4 | T6: 4 | U6: 16 | Z6: 10.079982 | AB6: 10.073521 | AC6: 10.079982 | AD6: 10.079982 | AE6: 11.354165 | AF6: 1.0395683 | AG6: 1.2714197 | AZ6: 1 | BA6: 1 | BB6: 2025-11-08_23h53.41.348 | BC6: word_priming_sp | BE6: 2025.1.1 | BF6: 120.77161 | BG6: 2025-11-08 23h53.47.999473 +0530
A7: esoteric | B7: 5 | C7: 5 | D7: 0 | E7: 1.0395683 | F7: 1.7562688 | R7: 0 | S7: 5 | T7: 5 | U7: 17 | Z7: 11.362748 | AB7: 11.356173 | AC7: 11.362748 | AD7: 11.362748 | AE7: 13.119709 | AF7: 1.0395683 | AG7: 1.7562688 | AZ7: 1 | BA7: 1 | BB7: 2025-11-08_23h53.41.348 | BC7: word_priming_sp | BE7: 2025.1.1 | BF7: 120.77161 | BG7: 2025-11-08 23h53.47.999473 +0530
A8: minimum | B8: 6 | C8: 6 | D8: 0 | E8: 1.0395683 | F8: 0.88992892 | R8: 0 | S8: 6 | T8: 6 | U8: 8 | Z8: 13.128843 | AB8: 13.121835 | AC8: 13.128843 | AD8: 13.128843 | AE8: 14.020846 | AF8: 1.0395683 | AG8: 0.88992892 | AZ8: 1 | BA8: 1 | BB8: 2025-11-08_23h53.41.348 | BC8: word_priming_sp | BE8: 2025.1.1 | BF8: 120.77161 | BG8: 2025-11-08 23h53.47.999473 +0530
A9: sandwich | B9: 7 | C9: 7 | D9: 0 | E9: 1.0395683 | F9: 0.82175312 | R9: 0 | S9: 7 | T9: 7 | U9: 2 | Z9: 14.030172 | AB9: 14.023483 | AC9: 14.030172 | AD9: 14.030172 | AE9: 14.854244 | AF9: 1.0395683 | AG9: 0.82175312 | AZ9: 1 | BA9: 1 | BB9: 2025-11-08_23h53.41.348 | BC9: word_priming_sp | BE9: 2025.1.1 | BF9: 120.77161 | BG9: 2025-11-08 23h53.47.999473 +0530
A10: vicarious | B10: 8 | C10: 8 | D10: 0 | E10: 1.0395683 | F10: 0.905076 | R10: 0 | S10: 8 | T10: 8 | U10: 19 | Z10: 14.863296 | AB10: 14.856856 | AC10: 14.863296 | AD10: 14.863296 | AE10: 15.770859 | AF10: 1.0395683 | AG10: 0.905076 | AZ10: 1 | BA10: 1 | BB10: 2025-11-08_23h53.41.348 | BC10: word_priming_sp | BE10: 2025.1.1 | BF10: 120.77161 | BG10: 2025-11-08 23h53.47.999473 +0530
A11: book | B11: 9 | C11: 9 | D11: 0 | E11: 1.0395683 | F11: 0.63874875 | R11: 0 | S11: 9 | T11: 9 | U11: 0 | Z11: 15.779265 | AB11: 15.772648 | AC11: 15.779265 | AD11: 15.779265 | AE11: 16.420733 | AF11: 1.0395683 | AG11: 0.63874875 | AZ11: 1 | BA11: 1 | BB11: 2025-11-08_23h53.41.348 | BC11: word_priming_sp | BE11: 2025.1.1 | BF11: 120.77161 | BG11: 2025-11-08 23h53.47.999473 +0530
A12: beguile | B12: 10 | C12: 10 | D12: 0 | E12: 1.0395683 | F12: 1.188211 | R12: 0 | S12: 10 | T12: 10 | U12: 14 | Z12: 16.429896 | AB12: 16.423165 | AC12: 16.429896 | AD12: 16.429896 | AE12: 17.620325 | AF12: 1.0395683 | AG12: 1.188211 | AZ12: 1 | BA12: 1 | BB12: 2025-11-08_23h53.41.348 | BC12: word_priming_sp | BE12: 2025.1.1 | BF12: 120.77161 | BG12: 2025-11-08 23h53.47.999473 +0530
A13: alluvium | B13: 11 | C13: 11 | D13: 0 | E13: 4.971223 | F13: 2.5226711 | R13: 0 | S13: 11 | T13: 11 | U13: 13 | Z13: 17.628937 | AB13: 17.622268 | AC13: 17.628937 | AD13: 17.628937 | AE13: 20.154208 | AF13: 4.971223 | AG13: 2.5226711 | AZ13: 1 | BA13: 1 | BB13: 2025-11-08_23h53.41.348 | BC13: word_priming_sp | BE13: 2025.1.1 | BF13: 120.77161 | BG13: 2025-11-08 23h53.47.999473 +0530
... A21: cruise | B21: 19 | C21: 19 | D21: 0 | E21: 1 | F21: 0.77243167 | R21: 0 | S21: 19 | T21: 19 | U21: 9 | Z21: 27.446036 | AB21: 27.439305 | AC21: 27.446036 | AD21: 27.446036 | AE21: 28.220594 | AF21: 1 | AG21: 0.77243167 | AZ21: 1 | BA21: 1 | BB21: 2025-11-08_23h53.41.348 | BC21: word_priming_sp | BE21: 2025.1.1 | BF21: 120.77161 | BG21: 2025-11-08 23h53.47.999473 +0530
B22: 0 | C22: 0 | D22: 0 | G22: _ru_s_ | H22: cruise | I22: old | J22: cruise | K22: [np.float64(-0.044964028776978415)] | L22: [np.float64(-0.30035971223021585)] | M22: [1] | N22: [0] | O22: [0] | P22: [5.44765574997291] | Q22: ['submit_text'] | V22: 0 | W22: 0 | X22: 0 | Y22: 9 | Z22: 28.239758 | AH22: 28.231422 | AI22: 28.239758 | AJ22: 28.239758 | AK22: 28.239758 | AL22: 0.0108415 | AM22: 33.679233 | AN22: cruise | AO22: [np.float64(-0.044964028776978415)] | AP22: [np.float64(-0.30035971223021585)] | AQ22: [1] | AR22: [0] | AS22: [0] | AT22: [5.44765574997291] | AU22: ['submit_text'] | AZ22: 1 | BA22: 1 | BB22: 2025-11-08_23h53.41.348 | BC22: word_priming_sp | BE22: 2025.1.1 | BF22: 120.77161 | BG22: 2025-11-08 23h53.47.999473 +0530
B23: 1 | C23: 1 | D23: 0 | G23: _i_a _io_s | H23: vicarious | I23: old | J23: ei | K23: [] | L23: [] | M23: [] | N23: [] | O23: [] | P23: [] | Q23: [] | V23: 0 | W23: 1 | X23: 1 | Y23: 19 | Z23: 33.690779 | AH23: 33.681429 | AI23: 33.690779 | AJ23: 33.690779 | AK23: 33.690779 | AL23: 0.0020650839 | AM23: 43.678657 | AN23: ei | AO23: [] | AP23: [] | AQ23: [] | AR23: [] | AS23: [] | AT23: [] | AU23: [] | AV23: 43.691149 | AW23: 43.691149 | AX23: 43.691149 | AY23: 9.9990759 | AZ23: 1 | BA23: 1 | BB23: 2025-11-08_23h53.41.348 | BC23: word_priming_sp | BE23: 2025.1.1 | BF23: 120.77161 | BG23: 2025-11-08 23h53.47.999473 +0530
B24: 2 | C24: 2 | D24: 0 | G24: _en_il | H24: pencil | I24: new | K24: [np.float64(0.019784172661870502)] | L24: [np.float64(-0.302158273381295)] | M24: [1] | N24: [0] | O24: [0] | P24: [6.144047166919336] | Q24: ['submit_text'] | V24: 0 | W24: 2 | X24: 2 | Y24: 22 | Z24: 43.691149 | AH24: 43.681723 | AI24: 43.691149 | AJ24: 43.691149 | AK24: 43.691149 | AL24: 0.0023614999 | AM24: 49.825964 | AO24: [np.float64(0.019784172661870502)] | AP24: [np.float64(-0.302158273381295)] | AQ24: [1] | AR24: [0] | AS24: [0] | AT24: [6.144047166919336] | AU24: ['submit_text'] | AZ24: 1 | BA24: 1 | BB24: 2025-11-08_23h53.41.348 | BC24: word_priming_sp | BE24: 2025.1.1 | BF24: 120.77161 | BG24: 2025-11-08 23h53.47.999473 +0530
B25: 3 | C25: 3 | D25: 0 | G25: e_o_ _r_c | H25: esoteric | I25: old | J25: esoteric | K25: [np.float64(0.006294964028776978)] | L25: [np.float64(-0.2994604316546763)] | M25: [1] | N25: [0] | O25: [0] | P25: [5.6182179159950465] | Q25: ['submit_text'] | V25: 0 | W25: 3 | X25: 3 | Y25: 17 | Z25: 49.837193 | AH25: 49.827941 | AI25: 49.837193 | AJ25: 49.837193 | AK25: 49.837193 | AL25: 0.001840167 | AM25: 55.446317 | AN25: esoteric | AO25: [np.float64(0.006294964028776978)] | AP25: [np.float64(-0.2994604316546763)] | AQ25: [1] | AR25: [0] | AS25: [0] | AT25: [5.6182179159950465] | AU25: ['submit_text'] | AZ25: 1 | BA25: 1 | BB25: 2025-11-08_23h53.41.348 | BC25: word_priming_sp | BE25: 2025.1.1 | BF25: 120.77161 | BG25: 2025-11-08 23h53.47.999473 +0530
B26: 4 | C26: 4 | D26: 0 | G26: sa_d_ _ c_ | H26: sandwich | I26: old | J26: sandwhich | K26: [] | L26: [] | M26: [] | N26: [] | O26: [] | P26: [] | Q26: [] | V26: 0 | W26: 4 | X26: 4 | Y26: 2 | Z26: 55.457816 | AH26: 55.449251 | AI26: 55.457816 | AJ26: 55.457816 | AK26: 55.457816 | AL26: 0.0028008751 | AM26: 65.444708 | AN26: sandwhich | AO26: [] | AP26: [] | AQ26: [] | AR26: [] | AS26: [] | AT26: [] | AU26: [] | AV26: 65.457434 | AW26: 65.457434 | AX26: 65.457434 | AY26: 9.9980502 | AZ26: 1 | BA26: 1 | BB26: 2025-11-08_23h53.41.348 | BC26: word_priming_sp | BE26: 2025.1.1 | BF26: 120.77161 | BG26: 2025-11-08 23h53.47.999473 +0530
B27: 5 | C27: 5 | D27: 0 | G27: c_m_r_ | H27: camera | I27: new | J27: camera | K27: [np.float64(0.08273381294964029), np.float64(0.05485611510791367)] | L27: [np.float64(-0.24280575539568344), np.float64(-0.3129496402877698)] | M27: [1, 1] | N27: [0, 0] | O27: [0, 0] | P27: [4.49948504101485, 5.381624165922403] | Q27: [None, 'submit_text'] | V27: 0 | W27: 5 | X27: 5 | Y27: 23 | Z27: 65.457434 | AH27: 65.447311 | AI27: 65.457434 | AJ27: 65.457434 | AK27: 65.457434 | AL27: 0.000864167 | AM27: 70.829161 | AN27: camera | AO27: [np.float64(0.08273381294964029), np.float64(0.05485611510791367)] | AP27: [np.float64(-0.24280575539568344), np.float64(-0.3129496402877698)] | AQ27: [1, 1] | AR27: [0, 0] | AS27: [0, 0] | AT27: [4.49948504101485, 5.381624165922403] | AU27: [None, 'submit_text'] | AZ27: 1 | BA27: 1 | BB27: 2025-11-08_23h53.41.348 | BC27: word_priming_sp | BE27: 2025.1.1 | BF27: 120.77161 | BG27: 2025-11-08 23h53.47.999473 +0530
B28: 6 | C28: 6 | D28: 0 | G28: b_gu_l_ | H28: beguile | I28: old | J28: beguile | K28: [np.float64(0.05485611510791367)] | L28: [np.float64(-0.31384892086330934)] | M28: [1] | N28: [0] | O28: [0] | P28: [4.3649273328483105] | Q28: ['submit_text'] | V28: 0 | W28: 6 | X28: 6 | Y28: 14 | Z28: 70.841038 | AH28: 70.831382 | AI28: 70.841038 | AJ28: 70.841038 | AK28: 70.841038 | AL28: 0.002084417 | AM28: 75.196531 | AN28: beguile | AO28: [np.float64(0.05485611510791367)] | AP28: [np.float64(-0.31384892086330934)] | AQ28: [1] | AR28: [0] | AS28: [0] | AT28: [4.3649273328483105] | AU28: ['submit_text'] | AZ28: 1 | BA28: 1 | BB28: 2025-11-08_23h53.41.348 | BC28: word_priming_sp | BE28: 2025.1.1 | BF28: 120.77161 | BG28: 2025-11-08 23h53.47.999473 +0530
B29: 7 | C29: 7 | D29: 0 | G29: _h_ls_ | H29: whilst | I29: old | K29: [np.float64(0.05485611510791367)] | L29: [np.float64(-0.31384892086330934)] | M29: [1] | N29: [0] | O29: [0] | P29: [4.979707333026454] | Q29: ['submit_text'] | V29: 0 | W29: 7 | X29: 7 | Y29: 7 | Z29: 75.207677 | AH29: 75.198877 | AI29: 75.207677 | AJ29: 75.207677 | AK29: 75.207677 | AL29: 0.002216666 | AM29: 80.178797 | AO29: [np.float64(0.05485611510791367)] | AP29: [np.float64(-0.31384892086330934)] | AQ29: [1] | AR29: [0] | AS29: [0] | AT29: [4.979707333026454] | AU29: ['submit_text'] | AZ29: 1 | BA29: 1 | BB29: 2025-11-08_23h53.41.348 | BC29: word_priming_sp | BE29: 2025.1.1 | BF29: 120.77161 | BG29: 2025-11-08 23h53.47.999473 +0530
B30: 8 | C30: 8 | D30: 0 | G30: o_sc_r_ | H30: obscure | I30: new | K30: [np.float64(0.05485611510791367)] | L30: [np.float64(-0.31384892086330934)] | M30: [1] | N30: [0] | O30: [0] | P30: [4.298369958996773] | Q30: ['submit_text'] | V30: 0 | W30: 8 | X30: 8 | Y30: 24 | Z30: 80.188574 | AH30: 80.180721 | AI30: 80.188574 | AJ30: 80.188574 | AK30: 80.188574 | AL30: 0.0018393751 | AM30: 84.479273 | AO30: [np.float64(0.05485611510791367)] | AP30: [np.float64(-0.31384892086330934)] | AQ30: [1] | AR30: [0] | AS30: [0] | AT30: [4.298369958996773] | AU30: ['submit_text'] | AZ30: 1 | BA30: 1 | BB30: 2025-11-08_23h53.41.348 | BC30: word_priming_sp | BE30: 2025.1.1 | BF30: 120.77161 | BG30: 2025-11-08 23h53.47.999473 +0530
B31: 9 | C31: 9 | D31: 0 | G31: _oo_h | H31: booth | I31: old | K31: [np.float64(0.05485611510791367)] | L31: [np.float64(-0.31384892086330934)] | M31: [1] | N31: [0] | O31: [0] | P31: [3.3468433341477066] | Q31: ['submit_text'] | V31: 0 | W31: 9 | X31: 9 | Y31: 5 | Z31: 84.489424 | AH31: 84.481427 | AI31: 84.489424 | AJ31: 84.489424 | AK31: 84.489424 | AL31: 0.0020605419 | AM31: 87.828466 | AO31: [np.float64(0.05485611510791367)] | AP31: [np.float64(-0.31384892086330934)] | AQ31: [1] | AR31: [0] | AS31: [0] | AT31: [3.3468433341477066] | AU31: ['submit_text'] | AZ31: 1 | BA31: 1 | BB31: 2025-11-08_23h53.41.348 | BC31: word_priming_sp | BE31: 2025.1.1 | BF31: 120.77161 | BG31: 2025-11-08 23h53.47.999473 +0530
B32: 10 | C32: 10 | D32: 0 | G32: _a_l_nc_ | H32: parlance | I32: old | K32: [np.float64(0.0737410071942446)] | L32: [np.float64(-0.3120503597122302)] | M32: [1] | N32: [0] | O32: [0] | P32: [2.83115854091011] | Q32: ['submit_text'] | V32: 0 | W32: 10 | X32: 10 | Y32: 11 | Z32: 87.853186 | AH32: 87.83005 | AI32: 87.853186 | AJ32: 87.853186 | AK32: 87.853186 | AL32: 0.0014956249 | AM32: 90.661363 | AO32: [np.float64(0.0737410071942446)] | AP32: [np.float64(-0.3120503597122302)] | AQ32: [1] | AR32: [0] | AS32: [0] | AT32: [2.83115854091011] | AU32: ['submit_text'] | AZ32: 1 | BA32: 1 | BB32: 2025-11-08_23h53.41.348 | BC32: word_priming_sp | BE32: 2025.1.1 | BF32: 120.77161 | BG32: 2025-11-08 23h53.47.999473 +0530
B33: 11 | C33: 11 | D33: 0 | G33: b_o_ | H33: book | I33: old | J33: booth | K33: [np.float64(0.0737410071942446)] | L33: [np.float64(-0.3120503597122302)] | M33: [1] | N33: [0] | O33: [0] | P33: [2.932598624844104] | Q33: ['submit_text'] | V33: 0 | W33: 11 | X33: 11 | Y33: 0 | Z33: 90.669808 | AH33: 90.662734 | AI33: 90.669808 | AJ33: 90.669808 | AK33: 90.669808 | AL33: 0.0012868331 | AM33: 93.595504 | AN33: booth | AO33: [np.float64(0.0737410071942446)] | AP33: [np.float64(-0.3120503597122302)] | AQ33: [1] | AR33: [0] | AS33: [0] | AT33: [2.932598624844104] | AU33: ['submit_text'] | AZ33: 1 | BA33: 1 | BB33: 2025-11-08_23h53.41.348 | BC33: word_priming_sp | BE33: 2025.1.1 | BF33: 120.77161 | BG33: 2025-11-08 23h53.47.999473 +0530
B34: 12 | C34: 12 | D34: 0 | G34: la_g_ _e_ | H34: laughter | I34: old | J34: langg | K34: [] | L34: [] | M34: [] | N34: [] | O34: [] | P34: [] | Q34: [] | V34: 0 | W34: 12 | X34: 12 | Y34: 6 | Z34: 93.607731 | AH34: 93.598073 | AI34: 93.607731 | AJ34: 93.607731 | AK34: 93.607731 | AL34: 0.002475458 | AM34: 103.59459 | AN34: langg | AO34: [] | AP34: [] | AQ34: [] | AR34: [] | AS34: [] | AT34: [] | AU34: [] | AV34: 103.60678 | AW34: 103.60678 | AX34: 103.60678 | AY34: 9.9988022 | AZ34: 1 | BA34: 1 | BB34: 2025-11-08_23h53.41.348 | BC34: word_priming_sp | BE34: 2025.1.1 | BF34: 120.77161 | BG34: 2025-11-08 23h53.47.999473 +0530
B35: 13 | C35: 13 | D35: 0 | G35: pa_s_m_ _y | H35: parsimony | I35: old | J35: passomany | K35: [np.float64(0.0737410071942446)] | L35: [np.float64(-0.3120503597122302)] | M35: [1] | N35: [0] | O35: [0] | P35: [9.584235292160884] | Q35: ['submit_text'] | V35: 0 | W35: 13 | X35: 13 | Y35: 18 | Z35: 103.60678 | AH35: 103.59709 | AI35: 103.60678 | AJ35: 103.60678 | AK35: 103.60678 | AL35: 0.001491833 | AM35: 113.18153 | AN35: passomany | AO35: [np.float64(0.0737410071942446)] | AP35: [np.float64(-0.3120503597122302)] | AQ35: [1] | AR35: [0] | AS35: [0] | AT35: [9.584235292160884] | AU35: ['submit_text'] | AZ35: 1 | BA35: 1 | BB35: 2025-11-08_23h53.41.348 | BC35: word_priming_sp | BE35: 2025.1.1 | BF35: 120.77161 | BG35: 2025-11-08 23h53.47.999473 +0530
B36: 14 | C36: 14 | D36: 0 | G36: _in_ _u_ | H36: minimum | I36: old | K36: [np.float64(0.0737410071942446)] | L36: [np.float64(-0.3120503597122302)] | M36: [1] | N36: [0] | O36: [0] | P36: [1.8106912919320166] | Q36: ['submit_text'] | V36: 0 | W36: 14 | X36: 14 | Y36: 8 | Z36: 113.1917 | AH36: 113.18385 | AI36: 113.1917 | AJ36: 113.1917 | AK36: 113.1917 | AL36: 0.0021847498 | AM36: 114.99473 | AO36: [np.float64(0.0737410071942446)] | AP36: [np.float64(-0.3120503597122302)] | AQ36: [1] | AR36: [0] | AS36: [0] | AT36: [1.8106912919320166] | AU36: ['submit_text'] | AZ36: 1 | BA36: 1 | BB36: 2025-11-08_23h53.41.348 | BC36: word_priming_sp | BE36: 2025.1.1 | BF36: 120.77161 | BG36: 2025-11-08 23h53.47.999473 +0530
B37: 15 | C37: 15 | D37: 0 | G37: p_ _e | H37: page | I37: new | J37: pipe | K37: [np.float64(0.0737410071942446)] | L37: [np.float64(-0.3120503597122302)] | M37: [1] | N37: [0] | O37: [0] | P37: [4.63202212494798] | Q37: ['submit_text'] | V37: 0 | W37: 15 | X37: 15 | Y37: 21 | Z37: 115.00381 | AH37: 114.99639 | AI37: 115.00381 | AJ37: 115.00381 | AK37: 115.00381 | AL37: 0.0015683342 | AM37: 119.62861 | AN37: pipe | AO37: [np.float64(0.0737410071942446)] | AP37: [np.float64(-0.3120503597122302)] | AQ37: [1] | AR37: [0] | AS37: [0] | AT37: [4.63202212494798] | AU37: ['submit_text'] | AZ37: 1 | BA37: 1 | BB37: 2025-11-08_23h53.41.348 | BC37: word_priming_sp | BE37: 2025.1.1 | BF37: 120.77161 | BG37: 2025-11-08 23h53.47.999473 +0530
B38: 16 | C38: 16 | D38: 0 | G38: ca_o_h_ _y | H38: cacophony | I38: old | J38: cacophony | K38: [np.float64(0.0737410071942446)] | L38: [np.float64(-0.3120503597122302)] | M38: [1] | N38: [0] | O38: [0] | P38: [5.4473572911228985] | Q38: ['submit_text'] | V38: 0 | W38: 16 | X38: 16 | Y38: 16 | Z38: 119.64047 | AH38: 119.63115 | AI38: 119.64047 | AJ38: 119.64047 | AK38: 119.64047 | AL38: 0.002430375 | AM38: 125.07873 | AN38: cacophony | AO38: [np.float64(0.0737410071942446)] | AP38: [np.float64(-0.3120503597122302)] | AQ38: [1] | AR38: [0] | AS38: [0] | AT38: [5.4473572911228985] | AU38: ['submit_text'] | AZ38: 1 | BA38: 1 | BB38: 2025-11-08_23h53.41.348 | BC38: word_priming_sp | BE38: 2025.1.1 | BF38: 120.77161 | BG38: 2025-11-08 23h53.47.999473 +0530
B39: 17 | C39: 17 | D39: 0 | G39: _os_ | H39: hose | I39: old | K39: [np.float64(0.08183453237410072)] | L39: [np.float64(-0.295863309352518)] | M39: [1] | N39: [0] | O39: [0] | P39: [2.1310519999824464] | Q39: ['submit_text'] | V39: 0 | W39: 17 | X39: 17 | Y39: 4 | Z39: 125.08984 | AH39: 125.08025 | AI39: 125.08984 | AJ39: 125.08984 | AK39: 125.08984 | AL39: 0.0014372091 | AM39: 127.21149 | AO39: [np.float64(0.08183453237410072)] | AP39: [np.float64(-0.295863309352518)] | AQ39: [1] | AR39: [0] | AS39: [0] | AT39: [2.1310519999824464] | AU39: ['submit_text'] | AZ39: 1 | BA39: 1 | BB39: 2025-11-08_23h53.41.348 | BC39: word_priming_sp | BE39: 2025.1.1 | BF39: 120.77161 | BG39: 2025-11-08 23h53.47.999473 +0530
B40: 18 | C40: 18 | D40: 0 | G40: _l_u_ia_ | H40: alluvium | I40: old | K40: [np.float64(-0.015287769784172662)] | L40: [np.float64(-0.32194244604316546)] | M40: [1] | N40: [0] | O40: [0] | P40: [6.181590208085254] | Q40: ['submit_text'] | V40: 0 | W40: 18 | X40: 18 | Y40: 13 | Z40: 127.22034 | AH40: 127.21311 | AI40: 127.22034 | AJ40: 127.22034 | AK40: 127.22034 | AL40: 0.0015332079 | AM40: 133.39489 | AO40: [np.float64(-0.015287769784172662)] | AP40: [np.float64(-0.32194244604316546)] | AQ40: [1] | AR40: [0] | AS40: [0] | AT40: [6.181590208085254] | AU40: ['submit_text'] | AZ40: 1 | BA40: 1 | BB40: 2025-11-08_23h53.41.348 | BC40: word_priming_sp | BE40: 2025.1.1 | BF40: 120.77161 | BG40: 2025-11-08 23h53.47.999473 +0530
B41: 19 | C41: 19 | D41: 0 | G41: c_ _hi_n | H41: cushion | I41: new | J41: cushion | K41: [np.float64(0.04316546762589928)] | L41: [np.float64(-0.3066546762589928)] | M41: [1] | N41: [0] | O41: [0] | P41: [4.882273209048435] | Q41: ['submit_text'] | V41: 0 | W41: 19 | X41: 19 | Y41: 20 | Z41: 133.41974 | AH41: 133.3968 | AI41: 133.41974 | AJ41: 133.41974 | AK41: 133.41974 | AL41: 0.001825084 | AM41: 138.27928 | AN41: cushion | AO41: [np.float64(0.04316546762589928)] | AP41: [np.float64(-0.3066546762589928)] | AQ41: [1] | AR41: [0] | AS41: [0] | AT41: [4.882273209048435] | AU41: ['submit_text'] | AZ41: 1 | BA41: 1 | BB41: 2025-11-08_23h53.41.348 | BC41: word_priming_sp | BE41: 2025.1.1 | BF41: 120.77161 | BG41: 2025-11-08 23h53.47.999473 +0530
B42: 20 | C42: 20 | D42: 0 | G42: _ a_pe_ | H42: carpet | I42: old | K42: [np.float64(0.044064748201438846)] | L42: [np.float64(-0.3066546762589928)] | M42: [1] | N42: [0] | O42: [0] | P42: [1.6794740830082446] | Q42: ['submit_text'] | V42: 0 | W42: 20 | X42: 20 | Y42: 1 | Z42: 138.29053 | AH42: 138.28157 | AI42: 138.29053 | AJ42: 138.29053 | AK42: 138.29053 | AL42: 0.0021952081 | AM42: 139.96127 | AO42: [np.float64(0.044064748201438846)] | AP42: [np.float64(-0.3066546762589928)] | AQ42: [1] | AR42: [0] | AS42: [0] | AT42: [1.6794740830082446] | AU42: ['submit_text'] | AZ42: 1 | BA42: 1 | BB42: 2025-11-08_23h53.41.348 | BC42: word_priming_sp | BE42: 2025.1.1 | BF42: 120.77161 | BG42: 2025-11-08 23h53.47.999473 +0530
B43: 21 | C43: 21 | D43: 0 | G43: _e_or_ | H43: memory | I43: old | K43: [np.float64(0.047661870503597124)] | L43: [np.float64(-0.2976618705035971)] | M43: [1] | N43: [0] | O43: [0] | P43: [1.9147910829633474] | Q43: ['submit_text'] | V43: 0 | W43: 21 | X43: 21 | Y43: 3 | Z43: 139.98628 | AH43: 139.96294 | AI43: 139.98628 | AJ43: 139.98628 | AK43: 139.98628 | AL43: 0.0016034169 | AM43: 141.87792 | AO43: [np.float64(0.047661870503597124)] | AP43: [np.float64(-0.2976618705035971)] | AQ43: [1] | AR43: [0] | AS43: [0] | AT43: [1.9147910829633474] | AU43: ['submit_text'] | AZ43: 1 | BA43: 1 | BB43: 2025-11-08_23h53.41.348 | BC43: word_priming_sp | BE43: 2025.1.1 | BF43: 120.77161 | BG43: 2025-11-08 23h53.47.999473 +0530
B44: 22 | C44: 22 | D44: 0 | G44: i_si_i_ | H44: insipid | I44: old | J44: irsisis | K44: [np.float64(0.047661870503597124)] | L44: [np.float64(-0.2976618705035971)] | M44: [1] | N44: [0] | O44: [0] | P44: [6.515966958133504] | Q44: ['submit_text'] | V44: 0 | W44: 22 | X44: 22 | Y44: 15 | Z44: 141.90297 | AH44: 141.87955 | AI44: 141.90297 | AJ44: 141.90297 | AK44: 141.90297 | AL44: 0.001552084 | AM44: 148.39572 | AN44: irsisis | AO44: [np.float64(0.047661870503597124)] | AP44: [np.float64(-0.2976618705035971)] | AQ44: [1] | AR44: [0] | AS44: [0] | AT44: [6.515966958133504] | AU44: ['submit_text'] | AZ44: 1 | BA44: 1 | BB44: 2025-11-08_23h53.41.348 | BC44: word_priming_sp | BE44: 2025.1.1 | BF44: 120.77161 | BG44: 2025-11-08 23h53.47.999473 +0530
B45: 23 | C45: 23 | D45: 0 | G45: a_da_i_ _s | H45: audacious | I45: old | J45: audacious | K45: [np.float64(0.047661870503597124)] | L45: [np.float64(-0.2976618705035971)] | M45: [1] | N45: [0] | O45: [0] | P45: [4.0475150409620255] | Q45: ['submit_text'] | V45: 0 | W45: 23 | X45: 23 | Y45: 12 | Z45: 148.40699 | AH45: 148.39819 | AI45: 148.40699 | AJ45: 148.40699 | AK45: 148.40699 | AL45: 0.0023818752 | AM45: 152.44595 | AN45: audacious | AO45: [np.float64(0.047661870503597124)] | AP45: [np.float64(-0.2976618705035971)] | AQ45: [1] | AR45: [0] | AS45: [0] | AT45: [4.0475150409620255] | AU45: ['submit_text'] | AZ45: 1 | BA45: 1 | BB45: 2025-11-08_23h53.41.348 | BC45: word_priming_sp | BE45: 2025.1.1 | BF45: 120.77161 | BG45: 2025-11-08 23h53.47.999473 +0530
B46: 24 | C46: 24 | D46: 0 | G46: _ui_ _ | H46: quill | I46: old | J46: quill | K46: [np.float64(0.047661870503597124)] | L46: [np.float64(-0.2976618705035971)] | M46: [1] | N46: [0] | O46: [0] | P46: [3.030242082895711] | Q46: ['submit_text'] | V46: 0 | W46: 24 | X46: 24 | Y46: 10 | Z46: 152.45703 | AH46: 152.44829 | AI46: 152.45703 | AJ46: 152.45703 | AK46: 152.45703 | AL46: 0.0022497079 | AM46: 155.47878 | AN46: quill | AO46: [np.float64(0.047661870503597124)] | AP46: [np.float64(-0.2976618705035971)] | AQ46: [1] | AR46: [0] | AS46: [0] | AT46: [3.030242082895711] | AU46: ['submit_text'] | AZ46: 1 | BA46: 1 | BB46: 2025-11-08_23h53.41.348 | BC46: word_priming_sp | BE46: 2025.1.1 | BF46: 120.77161 | BG46: 2025-11-08 23h53.47.999473 +0530
K49: prop hit from study list | L49: 6 by 12 | M49: =6/12 -> 0.5
...

Sheet 1.1 sleep
A1: study_word | B1: thisN | C1: thisTrialN | D1: thisRepN | E1: StudySlider.response | F1: StudySlider.rt | G1: test_word | H1: Reference | I1: old_new | J1: test_textbox.text | K1: testmouse.x | L1: testmouse.y | M1: testmouse.leftButton | N1: testmouse.midButton | O1: testmouse.rightButton | P1: testmouse.time | Q1: testmouse.clicked_name | R1: trials.thisRepN | S1: trials.thisTrialN | T1: trials.thisN | U1: trials.thisIndex | V1: trials_2.thisRepN | W1: trials_2.thisTrialN | X1: trials_2.thisN | Y1: trials_2.thisIndex | Z1: thisRow.t | AA1: notes | AB1: trial.started | AC1: StudyText.started | AD1: StudySlider.started | AE1: trial.stopped | AF1: trials.StudySlider.response | AG1: trials.StudySlider.rt | AH1: Test_Phase.started | AI1: TestText.started | AJ1: test_textbox.started | AK1: submit_text.started | AL1: testmouse.started | AM1: Test_Phase.stopped | AN1: trials_2.test_textbox.text | AO1: trials_2.testmouse.x | AP1: trials_2.testmouse.y | AQ1: trials_2.testmouse.leftButton | AR1: trials_2.testmouse.midButton | AS1: trials_2.testmouse.rightButton | AT1: trials_2.testmouse.time | AU1: trials_2.testmouse.clicked_name | AV1: TestText.stopped | AW1: test_textbox.stopped | AX1: submit_text.stopped | AY1: testmouse.stopped | AZ1: participant | BA1: session | BB1: date | BC1: expName | BD1: expVersion | BE1: psychopyVersion | BF1: frameRate | BG1: expStart
A2: quill | B2: 0 | C2: 0 | D2: 0 | E2: 1.0251799 | F2: 2.6180784 | R2: 0 | S2: 0 | T2: 0 | U2: 10 | Z2: 0.0370785 | AB2: 0.018378833 | AC2: 0.0370785 | AD2: 0.0370785 | AE2: 2.6454377 | AF2: 1.0251799 | AG2: 2.6180784 | AZ2: 1.1 | BA2: 1 | BB2: 2025-11-09_11h41.23.238 | BC2: word_priming_sp | BE2: 2025.1.1 | BF2: None | BG2: 2025-11-09 11h41.40.626864 +0530
A3: esoteric | B3: 1 | C3: 1 | D3: 0 | E3: 1 | F3: 2.4047201 | R3: 0 | S3: 1 | T3: 1 | U3: 17 | Z3: 2.6554345 | AB3: 2.6488095 | AC3: 2.6554345 | AD3: 2.6554345 | AE3: 5.0625435 | AF3: 1 | AG3: 2.4047201 | AZ3: 1.1 | BA3: 1 | BB3: 2025-11-09_11h41.23.238 | BC3: word_priming_sp | BE3: 2025.1.1 | BF3: None | BG3: 2025-11-09 11h41.40.626864 +0530
A4: vicarious | B4: 2 | C4: 2 | D4: 0 | E4: 1 | F4: 2.539197 | R4: 0 | S4: 2 | T4: 2 | U4: 19 | Z4: 5.0721188 | AB4: 5.0655058 | AC4: 5.0721188 | AD4: 5.0721188 | AE4: 7.6122144 | AF4: 1 | AG4: 2.539197 | AZ4: 1.1 | BA4: 1 | BB4: 2025-11-09_11h41.23.238 | BC4: word_priming_sp | BE4: 2025.1.1 | BF4: None | BG4: 2025-11-09 11h41.40.626864 +0530
A5: booth | B5: 3 | C5: 3 | D5: 0 | E5: 1 | F5: 1.254909 | R5: 0 | S5: 3 | T5: 3 | U5: 5 | Z5: 7.6216102 | AB5: 7.615097 | AC5: 7.6216102 | AD5: 7.6216102 | AE5: 8.8792132 | AF5: 1 | AG5: 1.254909 | AZ5: 1.1 | BA5: 1 | BB5: 2025-11-09_11h41.23.238 | BC5: word_priming_sp | BE5: 2025.1.1 | BF5: None | BG5: 2025-11-09 11h41.40.626864 +0530
A6: beguile | B6: 4 | C6: 4 | D6: 0 | E6: 1 | F6: 1.5550155 | R6: 0 | S6: 4 | T6: 4 | U6: 14 | Z6: 8.888258 | AB6: 8.8817607 | AC6: 8.888258 | AD6: 8.888258 | AE6: 10.445878 | AF6: 1 | AG6: 1.5550155 | AZ6: 1.1 | BA6: 1 | BB6: 2025-11-09_11h41.23.238 | BC6: word_priming_sp | BE6: 2025.1.1 | BF6: None | BG6: 2025-11-09 11h41.40.626864 +0530
A7: insipid | B7: 5 | C7: 5 | D7: 0 | E7: 1 | F7: 1.904256 | R7: 0 | S7: 5 | T7: 5 | U7: 15 | Z7: 10.455516 | AB7: 10.449003 | AC7: 10.455516 | AD7: 10.455516 | AE7: 12.362464 | AF7: 1 | AG7: 1.904256 | AZ7: 1.1 | BA7: 1 | BB7: 2025-11-09_11h41.23.238 | BC7: word_priming_sp | BE7: 2025.1.1 | BF7: None | BG7: 2025-11-09 11h41.40.626864 +0530
A8: parlance | B8: 6 | C8: 6 | D8: 0 | E8: 4.971223 | F8: 3.0889661 | R8: 0 | S8: 6 | T8: 6 | U8: 11 | Z8: 12.370725 | AB8: 12.36431 | AC8: 12.370725 | AD8: 12.370725 | AE8: 15.462383 | AF8: 4.971223 | AG8: 3.0889661 | AZ8: 1.1 | BA8: 1 | BB8: 2025-11-09_11h41.23.238 | BC8: word_priming_sp | BE8: 2025.1.1 | BF8: None | BG8: 2025-11-09 11h41.40.626864 +0530
A9: hose | B9: 7 | C9: 7 | D9: 0 | E9: 1 | F9: 2.0556547 | R9: 0 | S9: 7 | T9: 7 | U9: 4 | Z9: 15.470931 | AB9: 15.464144 | AC9: 15.470931 | AD9: 15.470931 | AE9: 17.529117 | AF9: 1 | AG9: 2.0556547 | AZ9: 1.1 | BA9: 1 | BB9: 2025-11-09_11h41.23.238 | BC9: word_priming_sp | BE9: 2025.1.1 | BF9: None | BG9: 2025-11-09 11h41.40.626864 +0530
A10: book | B10: 8 | C10: 8 | D10: 0 | E10: 1 | F10: 1.1228307 | R10: 0 | S10: 8 | T10: 8 | U10: 0 | Z10: 17.537105 | AB10: 17.530627 | AC10: 17.537105 | AD10: 17.537105 | AE10: 18.66261 | AF10: 1 | AG10: 1.1228307 | AZ10: 1.1 | BA10: 1 | BB10: 2025-11-09_11h41.23.238 | BC10: word_priming_sp | BE10: 2025.1.1 | BF10: None | BG10: 2025-11-09 11h41.40.626864 +0530
A11: memory | B11: 9 | C11: 9 | D11: 0 | E11: 1 | F11: 1.7714773 | R11: 0 | S11: 9 | T11: 9 | U11: 3 | Z11: 18.672115 | AB11: 18.665487 | AC11: 18.672115 | AD11: 18.672115 | AE11: 20.445843 | AF11: 1 | AG11: 1.7714773 | AZ11: 1.1 | BA11: 1 | BB11: 2025-11-09_11h41.23.238 | BC11: word_priming_sp | BE11: 2025.1.1 | BF11: None | BG11: 2025-11-09 11h41.40.626864 +0530
A12: whilst | B12: 10 | C12: 10 | D12: 0 | E12: 1 | F12: 1.1879777 | R12: 0 | S12: 10 | T12: 10 | U12: 7 | Z12: 20.455105 | AB12: 20.448569 | AC12: 20.455105 | AD12: 20.455105 | AE12: 21.645755 | AF12: 1 | AG12: 1.1879777 | AZ12: 1.1 | BA12: 1 | BB12: 2025-11-09_11h41.23.238 | BC12: word_priming_sp | BE12: 2025.1.1 | BF12: None | BG12: 2025-11-09 11h41.40.626864 +0530
A13: audacious | B13: 11 | C13: 11 | D13: 0 | E13: 1 | F13: 1.4558773 | R13: 0 | S13: 11 | T13: 11 | U13: 12 | Z13: 21.653947 | AB13: 21.647479 | AC13: 21.653947 | AD13: 21.653947 | AE13: 23.112367 | AF13: 1 | AG13: 1.4558773 | AZ13: 1.1 | BA13: 1 | BB13: 2025-11-09_11h41.23.238 | BC13: word_priming_sp | BE13: 2025.1.1 | BF13: None | BG13: 2025-11-09 11h41.40.626864 +0530
... A21: cruise | B21: 19 | C21: 19 | D21: 0 | E21: 1.0251799 | F21: 1.6053617 | R21: 0 | S21: 19 | T21: 19 | U21: 9 | Z21: 41.4544 | AB21: 41.447809 | AC21: 41.4544 | AD21: 41.4544 | AE21: 43.062352 | AF21: 1.0251799 | AG21: 1.6053617 | AZ21: 1.1 | BA21: 1 | BB21: 2025-11-09_11h41.23.238 | BC21: word_priming_sp | BE21: 2025.1.1 | BF21: None | BG21: 2025-11-09 11h41.40.626864 +0530
B22: 0 | C22: 0 | D22: 0 | G22: pa_s_m_ _y | H22: parsimony | I22: old | J22: passomany | K22: [] | L22: [] | M22: [] | N22: [] | O22: [] | P22: [] | Q22: [] | V22: 0 | W22: 0 | X22: 0 | Y22: 18 | Z22: 43.080168 | AH22: 43.071732 | AI22: 43.080168 | AJ22: 43.080168 | AK22: 43.080168 | AL22: 0.009383209 | AM22: 53.069142 | AN22: passomany | AO22: [] | AP22: [] | AQ22: [] | AR22: [] | AS22: [] | AT22: [] | AU22: [] | AZ22: 1.1 | BA22: 1 | BB22: 2025-11-09_11h41.23.238 | BC22: word_priming_sp | BE22: 2025.1.1 | BF22: None | BG22: 2025-11-09 11h41.40.626864 +0530
B23: 1 | C23: 1 | D23: 0 | G23: ca_o_h_ _y | H23: cacophony | I23: old | J23: cacophony | K23: [np.float64(0.006294964028776978)] | L23: [np.float64(-0.3255395683453237)] | M23: [1] | N23: [0] | O23: [0] | P23: [5.917098707985133] | Q23: ['submit_text'] | V23: 0 | W23: 1 | X23: 1 | Y23: 16 | Z23: 53.081853 | AH23: 53.072272 | AI23: 53.081853 | AJ23: 53.081853 | AK23: 53.081853 | AL23: 0.0099284591 | AM23: 58.989575 | AN23: cacophony | AO23: [np.float64(0.006294964028776978)] | AP23: [np.float64(-0.3255395683453237)] | AQ23: [1] | AR23: [0] | AS23: [0] | AT23: [5.917098707985133] | AU23: ['submit_text'] | AZ23: 1.1 | BA23: 1 | BB23: 2025-11-09_11h41.23.238 | BC23: word_priming_sp | BE23: 2025.1.1 | BF23: None | BG23: 2025-11-09 11h41.40.626864 +0530
B24: 2 | C24: 2 | D24: 0 | G24: _in_ _u_ | H24: minimum | I24: old | K24: [np.float64(0.006294964028776978)] | L24: [np.float64(-0.3255395683453237)] | M24: [1] | N24: [0] | O24: [0] | P24: [6.978550833882764] | Q24: ['submit_text'] | V24: 0 | W24: 2 | X24: 2 | Y24: 8 | Z24: 59.000883 | AH24: 58.992109 | AI24: 59.000883 | AJ24: 59.000883 | AK24: 59.000883 | AL24: 0.0023797089 | AM24: 65.970833 | AO24: [np.float64(0.006294964028776978)] | AP24: [np.float64(-0.3255395683453237)] | AQ24: [1] | AR24: [0] | AS24: [0] | AT24: [6.978550833882764] | AU24: ['submit_text'] | AZ24: 1.1 | BA24: 1 | BB24: 2025-11-09_11h41.23.238 | BC24: word_priming_sp | BE24: 2025.1.1 | BF24: None | BG24: 2025-11-09 11h41.40.626864 +0530
B25: 3 | C25: 3 | D25: 0 | G25: _l_u_ia_ | H25: alluvium | I25: old | K25: [np.float64(0.006294964028776978)] | L25: [np.float64(-0.3255395683453237)] | M25: [1] | N25: [0] | O25: [0] | P25: [5.797077709110454] | Q25: ['submit_text'] | V25: 0 | W25: 3 | X25: 3 | Y25: 13 | Z25: 65.980405 | AH25: 65.972665 | AI25: 65.980405 | AJ25: 65.980405 | AK25: 65.980405 | AL25: 0.001744458 | AM25: 71.769884 | AO25: [np.float64(0.006294964028776978)] | AP25: [np.float64(-0.3255395683453237)] | AQ25: [1] | AR25: [0] | AS25: [0] | AT25: [5.797077709110454] | AU25: ['submit_text'] | AZ25: 1.1 | BA25: 1 | BB25: 2025-11-09_11h41.23.238 | BC25: word_priming_sp | BE25: 2025.1.1 | BF25: None | BG25: 2025-11-09 11h41.40.626864 +0530
B26: 4 | C26: 4 | D26: 0 | G26: e_o_ _r_c | H26: esoteric | I26: old | J26: esoteric | K26: [np.float64(0.006294964028776978)] | L26: [np.float64(-0.3255395683453237)] | M26: [1] | N26: [0] | O26: [0] | P26: [9.699310750002041] | Q26: ['submit_text'] | V26: 0 | W26: 4 | X26: 4 | Y26: 17 | Z26: 71.794909 | AH26: 71.771751 | AI26: 71.794909 | AJ26: 71.794909 | AK26: 71.794909 | AL26: 0.001768833 | AM26: 81.471221 | AN26: esoteric | AO26: [np.float64(0.006294964028776978)] | AP26: [np.float64(-0.3255395683453237)] | AQ26: [1] | AR26: [0] | AS26: [0] | AT26: [9.699310750002041] | AU26: ['submit_text'] | AZ26: 1.1 | BA26: 1 | BB26: 2025-11-09_11h41.23.238 | BC26: word_priming_sp | BE26: 2025.1.1 | BF26: None | BG26: 2025-11-09 11h41.40.626864 +0530
B27: 5 | C27: 5 | D27: 0 | G27: i_si_i_ | H27: insipid | I27: old | J27: insipid | K27: [np.float64(0.006294964028776978)] | L27: [np.float64(-0.3255395683453237)] | M27: [1] | N27: [0] | O27: [0] | P27: [4.314397167181596] | Q27: ['submit_text'] | V27: 0 | W27: 5 | X27: 5 | Y27: 15 | Z27: 81.482306 | AH27: 81.473356 | AI27: 81.482306 | AJ27: 81.482306 | AK27: 81.482306 | AL27: 0.0020325829 | AM27: 85.787956 | AN27: insipid | AO27: [np.float64(0.006294964028776978)] | AP27: [np.float64(-0.3255395683453237)] | AQ27: [1] | AR27: [0] | AS27: [0] | AT27: [4.314397167181596] | AU27: ['submit_text'] | AZ27: 1.1 | BA27: 1 | BB27: 2025-11-09_11h41.23.238 | BC27: word_priming_sp | BE27: 2025.1.1 | BF27: None | BG27: 2025-11-09 11h41.40.626864 +0530
B28: 6 | C28: 6 | D28: 0 | G28: _h_ls_ | H28: whilst | I28: old | K28: [np.float64(0.006294964028776978)] | L28: [np.float64(-0.3255395683453237)] | M28: [1] | N28: [0] | O28: [0] | P28: [4.230463500134647] | Q28: ['submit_text'] | V28: 0 | W28: 6 | X28: 6 | Y28: 7 | Z28: 85.799022 | AH28: 85.789963 | AI28: 85.799022 | AJ28: 85.799022 | AK28: 85.799022 | AL28: 0.0019143331 | AM28: 90.020611 | AO28: [np.float64(0.006294964028776978)] | AP28: [np.float64(-0.3255395683453237)] | AQ28: [1] | AR28: [0] | AS28: [0] | AT28: [4.230463500134647] | AU28: ['submit_text'] | AZ28: 1.1 | BA28: 1 | BB28: 2025-11-09_11h41.23.238 | BC28: word_priming_sp | BE28: 2025.1.1 | BF28: None | BG28: 2025-11-09 11h41.40.626864 +0530
B29: 7 | C29: 7 | D29: 0 | G29: sa_d_ _ c_ | H29: sandwich | I29: old | J29: samdwich | K29: [np.float64(0.006294964028776978)] | L29: [np.float64(-0.3255395683453237)] | M29: [1] | N29: [0] | O29: [0] | P29: [4.2980505840387195] | Q29: ['submit_text'] | V29: 0 | W29: 7 | X29: 7 | Y29: 2 | Z29: 90.030529 | AH29: 90.022586 | AI29: 90.030529 | AJ29: 90.030529 | AK29: 90.030529 | AL29: 0.0018903329 | AM29: 94.320808 | AN29: samdwich | AO29: [np.float64(0.006294964028776978)] | AP29: [np.float64(-0.3255395683453237)] | AQ29: [1] | AR29: [0] | AS29: [0] | AT29: [4.2980505840387195] | AU29: ['submit_text'] | AZ29: 1.1 | BA29: 1 | BB29: 2025-11-09_11h41.23.238 | BC29: word_priming_sp | BE29: 2025.1.1 | BF29: None | BG29: 2025-11-09 11h41.40.626864 +0530
B30: 8 | C30: 8 | D30: 0 | G30: b_o_ | H30: book | I30: old | J30: book | K30: [np.float64(0.006294964028776978)] | L30: [np.float64(-0.3255395683453237)] | M30: [1] | N30: [0] | O30: [0] | P30: [2.2978427498601377] | Q30: ['submit_text'] | V30: 0 | W30: 8 | X30: 8 | Y30: 0 | Z30: 94.332114 | AH30: 94.322699 | AI30: 94.332114 | AJ30: 94.332114 | AK30: 94.332114 | AL30: 0.0017993751 | AM30: 96.620742 | AN30: book | AO30: [np.float64(0.006294964028776978)] | AP30: [np.float64(-0.3255395683453237)] | AQ30: [1] | AR30: [0] | AS30: [0] | AT30: [2.2978427498601377] | AU30: ['submit_text'] | AZ30: 1.1 | BA30: 1 | BB30: 2025-11-09_11h41.23.238 | BC30: word_priming_sp | BE30: 2025.1.1 | BF30: None | BG30: 2025-11-09 11h41.40.626864 +0530
B31: 9 | C31: 9 | D31: 0 | G31: _ui_ _ | H31: quill | I31: old | K31: [np.float64(0.006294964028776978)] | L31: [np.float64(-0.3255395683453237)] | M31: [1] | N31: [0] | O31: [0] | P31: [9.113403333118185] | Q31: ['submit_text'] | V31: 0 | W31: 9 | X31: 9 | Y31: 10 | Z31: 96.632152 | AH31: 96.623053 | AI31: 96.632152 | AJ31: 96.632152 | AK31: 96.632152 | AL31: 0.002220667 | AM31: 105.73664 | AO31: [np.float64(0.006294964028776978)] | AP31: [np.float64(-0.3255395683453237)] | AQ31: [1] | AR31: [0] | AS31: [0] | AT31: [9.113403333118185] | AU31: ['submit_text'] | AZ31: 1.1 | BA31: 1 | BB31: 2025-11-09_11h41.23.238 | BC31: word_priming_sp | BE31: 2025.1.1 | BF31: None | BG31: 2025-11-09 11h41.40.626864 +0530
B32: 10 | C32: 10 | D32: 0 | G32: b_gu_l_ | H32: beguile | I32: old | J32: beguile | K32: [np.float64(0.006294964028776978)] | L32: [np.float64(-0.3255395683453237)] | M32: [1] | N32: [0] | O32: [0] | P32: [6.432792374864221] | Q32: ['submit_text'] | V32: 0 | W32: 10 | X32: 10 | Y32: 14 | Z32: 105.7614 | AH32: 105.73838 | AI32: 105.7614 | AJ32: 105.7614 | AK32: 105.7614 | AL32: 0.001644542 | AM32: 112.17135 | AN32: beguile | AO32: [np.float64(0.006294964028776978)] | AP32: [np.float64(-0.3255395683453237)] | AQ32: [1] | AR32: [0] | AS32: [0] | AT32: [6.432792374864221] | AU32: ['submit_text'] | AZ32: 1.1 | BA32: 1 | BB32: 2025-11-09_11h41.23.238 | BC32: word_priming_sp | BE32: 2025.1.1 | BF32: None | BG32: 2025-11-09 11h41.40.626864 +0530
B33: 11 | C33: 11 | D33: 0 | G33: _ru_s_ | H33: cruise | I33: old | J33: cruise | K33: [np.float64(0.006294964028776978)] | L33: [np.float64(-0.3255395683453237)] | M33: [1] | N33: [0] | O33: [0] | P33: [6.047726624878123] | Q33: ['submit_text'] | V33: 0 | W33: 11 | X33: 11 | Y33: 9 | Z33: 112.18249 | AH33: 112.17365 | AI33: 112.18249 | AJ33: 112.18249 | AK33: 112.18249 | AL33: 0.002168542 | AM33: 118.2216 | AN33: cruise | AO33: [np.float64(0.006294964028776978)] | AP33: [np.float64(-0.3255395683453237)] | AQ33: [1] | AR33: [0] | AS33: [0] | AT33: [6.047726624878123] | AU33: ['submit_text'] | AZ33: 1.1 | BA33: 1 | BB33: 2025-11-09_11h41.23.238 | BC33: word_priming_sp | BE33: 2025.1.1 | BF33: None | BG33: 2025-11-09 11h41.40.626864 +0530
B34: 12 | C34: 12 | D34: 0 | G34: _ a_pe_ | H34: carpet | I34: old | J34: carpet | K34: [np.float64(0.006294964028776978)] | L34: [np.float64(-0.3255395683453237)] | M34: [1] | N34: [0] | O34: [0] | P34: [4.463749582879245] | Q34: ['submit_text'] | V34: 0 | W34: 12 | X34: 12 | Y34: 1 | Z34: 118.23273 | AH34: 118.22392 | AI34: 118.23273 | AJ34: 118.23273 | AK34: 118.23273 | AL34: 0.0022132921 | AM34: 122.68788 | AN34: carpet | AO34: [np.float64(0.006294964028776978)] | AP34: [np.float64(-0.3255395683453237)] | AQ34: [1] | AR34: [0] | AS34: [0] | AT34: [4.463749582879245] | AU34: ['submit_text'] | AZ34: 1.1 | BA34: 1 | BB34: 2025-11-09_11h41.23.238 | BC34: word_priming_sp | BE34: 2025.1.1 | BF34: None | BG34: 2025-11-09 11h41.40.626864 +0530
B35: 13 | C35: 13 | D35: 0 | G35: _e_or_ | H35: memory | I35: old | K35: [np.float64(0.006294964028776978)] | L35: [np.float64(-0.3255395683453237)] | M35: [1] | N35: [0] | O35: [0] | P35: [5.013231749879196] | Q35: ['submit_text'] | V35: 0 | W35: 13 | X35: 13 | Y35: 3 | Z35: 122.69877 | AH35: 122.68995 | AI35: 122.69877 | AJ35: 122.69877 | AK35: 122.69877 | AL35: 0.0019765832 | AM35: 127.70339 | AO35: [np.float64(0.006294964028776978)] | AP35: [np.float64(-0.3255395683453237)] | AQ35: [1] | AR35: [0] | AS35: [0] | AT35: [5.013231749879196] | AU35: ['submit_text'] | AZ35: 1.1 | BA35: 1 | BB35: 2025-11-09_11h41.23.238 | BC35: word_priming_sp | BE35: 2025.1.1 | BF35: None | BG35: 2025-11-09 11h41.40.626864 +0530
B36: 14 | C36: 14 | D36: 0 | G36: _oo_h | H36: booth | I36: old | J36: booth | K36: [np.float64(0.006294964028776978)] | L36: [np.float64(-0.3255395683453237)] | M36: [1] | N36: [0] | O36: [0] | P36: [3.2992546251043677] | Q36: ['submit_text'] | V36: 0 | W36: 14 | X36: 14 | Y36: 5 | Z36: 127.72798 | AH36: 127.70502 | AI36: 127.72798 | AJ36: 127.72798 | AK36: 127.72798 | AL36: 0.0015517909 | AM36: 131.00447 | AN36: booth | AO36: [np.float64(0.006294964028776978)] | AP36: [np.float64(-0.3255395683453237)] | AQ36: [1] | AR36: [0] | AS36: [0] | AT36: [3.2992546251043677] | AU36: ['submit_text'] | AZ36: 1.1 | BA36: 1 | BB36: 2025-11-09_11h41.23.238 | BC36: word_priming_sp | BE36: 2025.1.1 | BF36: None | BG36: 2025-11-09 11h41.40.626864 +0530
B37: 15 | C37: 15 | D37: 0 | G37: c_m_r_ | H37: camera | I37: new | J37: camera | K37: [np.float64(0.006294964028776978)] | L37: [np.float64(-0.3255395683453237)] | M37: [1] | N37: [0] | O37: [0] | P37: [4.247408541850746] | Q37: ['submit_text'] | V37: 0 | W37: 15 | X37: 15 | Y37: 23 | Z37: 131.01544 | AH37: 131.00662 | AI37: 131.01544 | AJ37: 131.01544 | AK37: 131.01544 | AL37: 0.002059042 | AM37: 135.25425 | AN37: camera | AO37: [np.float64(0.006294964028776978)] | AP37: [np.float64(-0.3255395683453237)] | AQ37: [1] | AR37: [0] | AS37: [0] | AT37: [4.247408541850746] | AU37: ['submit_text'] | AZ37: 1.1 | BA37: 1 | BB37: 2025-11-09_11h41.23.238 | BC37: word_priming_sp | BE37: 2025.1.1 | BF37: None | BG37: 2025-11-09 11h41.40.626864 +0530
B38: 16 | C38: 16 | D38: 0 | G38: la_g_ _e_ | H38: laughter | I38: old | J38: m | K38: [] | L38: [] | M38: [] | N38: [] | O38: [] | P38: [] | Q38: [] | V38: 0 | W38: 16 | X38: 16 | Y38: 6 | Z38: 135.26572 | AH38: 135.25686 | AI38: 135.26572 | AJ38: 135.26572 | AK38: 135.26572 | AL38: 0.0025212499 | AM38: 145.25272 | AN38: m | AO38: [] | AP38: [] | AQ38: [] | AR38: [] | AS38: [] | AT38: [] | AU38: [] | AV38: 145.26472 | AW38: 145.26472 | AX38: 145.26472 | AY38: 9.9981523 | AZ38: 1.1 | BA38: 1 | BB38: 2025-11-09_11h41.23.238 | BC38: word_priming_sp | BE38: 2025.1.1 | BF38: None | BG38: 2025-11-09 11h41.40.626864 +0530
B39: 17 | C39: 17 | D39: 0 | G39: _i_a _io_s | H39: vicarious | I39: old | K39: [np.float64(0.06025179856115108)] | L39: [np.float64(-0.2994604316546763)] | M39: [1] | N39: [0] | O39: [0] | P39: [6.2810595410410315] | Q39: ['submit_text'] | V39: 0 | W39: 17 | X39: 17 | Y39: 19 | Z39: 145.26472 | AH39: 145.25553 | AI39: 145.26472 | AJ39: 145.26472 | AK39: 145.26472 | AL39: 0.0011962501 | AM39: 151.53685 | AO39: [np.float64(0.06025179856115108)] | AP39: [np.float64(-0.2994604316546763)] | AQ39: [1] | AR39: [0] | AS39: [0] | AT39: [6.2810595410410315] | AU39: ['submit_text'] | AZ39: 1.1 | BA39: 1 | BB39: 2025-11-09_11h41.23.238 | BC39: word_priming_sp | BE39: 2025.1.1 | BF39: None | BG39: 2025-11-09 11h41.40.626864 +0530
B40: 18 | C40: 18 | D40: 0 | G40: _a_l_nc_ | H40: parlance | I40: old | K40: [np.float64(-0.044964028776978415)] | L40: [np.float64(-0.2976618705035971)] | M40: [1] | N40: [0] | O40: [0] | P40: [3.5475599579513073] | Q40: ['submit_text'] | V40: 0 | W40: 18 | X40: 18 | Y40: 11 | Z40: 151.54672 | AH40: 151.53853 | AI40: 151.54672 | AJ40: 151.54672 | AK40: 151.54672 | AL40: 0.00160275 | AM40: 155.08628 | AO40: [np.float64(-0.044964028776978415)] | AP40: [np.float64(-0.2976618705035971)] | AQ40: [1] | AR40: [0] | AS40: [0] | AT40: [3.5475599579513073] | AU40: ['submit_text'] | AZ40: 1.1 | BA40: 1 | BB40: 2025-11-09_11h41.23.238 | BC40: word_priming_sp | BE40: 2025.1.1 | BF40: None | BG40: 2025-11-09 11h41.40.626864 +0530
B41: 19 | C41: 19 | D41: 0 | G41: _en_il | H41: pencil | I41: new | K41: [np.float64(-0.044964028776978415)] | L41: [np.float64(-0.2976618705035971)] | M41: [1] | N41: [0] | O41: [0] | P41: [4.515213167062029] | Q41: ['submit_text'] | V41: 0 | W41: 19 | X41: 19 | Y41: 22 | Z41: 155.09531 | AH41: 155.08791 | AI41: 155.09531 | AJ41: 155.09531 | AK41: 155.09531 | AL41: 0.0015556659 | AM41: 159.60329 | AO41: [np.float64(-0.044964028776978415)] | AP41: [np.float64(-0.2976618705035971)] | AQ41: [1] | AR41: [0] | AS41: [0] | AT41: [4.515213167062029] | AU41: ['submit_text'] | AZ41: 1.1 | BA41: 1 | BB41: 2025-11-09_11h41.23.238 | BC41: word_priming_sp | BE41: 2025.1.1 | BF41: None | BG41: 2025-11-09 11h41.40.626864 +0530
B42: 20 | C42: 20 | D42: 0 | G42: _os_ | H42: hose | I42: old | J42: boss | K42: [np.float64(-0.044964028776978415)] | L42: [np.float64(-0.2976618705035971)] | M42: [1] | N42: [0] | O42: [0] | P42: [5.8495117500424385] | Q42: ['submit_text'] | V42: 0 | W42: 20 | X42: 20 | Y42: 4 | Z42: 159.62783 | AH42: 159.60478 | AI42: 159.62783 | AJ42: 159.62783 | AK42: 159.62783 | AL42: 0.0013931249 | AM42: 165.45448 | AN42: boss | AO42: [np.float64(-0.044964028776978415)] | AP42: [np.float64(-0.2976618705035971)] | AQ42: [1] | AR42: [0] | AS42: [0] | AT42: [5.8495117500424385] | AU42: ['submit_text'] | AZ42: 1.1 | BA42: 1 | BB42: 2025-11-09_11h41.23.238 | BC42: word_priming_sp | BE42: 2025.1.1 | BF42: None | BG42: 2025-11-09 11h41.40.626864 +0530
B43: 21 | C43: 21 | D43: 0 | G43: c_ _hi_n | H43: cushion | I43: new | J43: cushion | K43: [np.float64(-0.3444244604316547), np.float64(0.01618705035971223)] | L43: [np.float64(-0.24280575539568344), np.float64(-0.2949640287769784)] | M43: [1, 1] | N43: [0, 0] | O43: [0, 0] | P43: [4.246590833179653, 6.03059170814231] | Q43: [None, 'submit_text'] | V43: 0 | W43: 21 | X43: 21 | Y43: 20 | Z43: 165.46534 | AH43: 165.45666 | AI43: 165.46534 | AJ43: 165.46534 | AK43: 165.46534 | AL43: 0.002094625 | AM43: 171.48748 | AN43: cushion | AO43: [np.float64(-0.3444244604316547), np.float64(0.01618705035971223)] | AP43: [np.float64(-0.24280575539568344), np.float64(-0.2949640287769784)] | AQ43: [1, 1] | AR43: [0, 0] | AS43: [0, 0] | AT43: [4.246590833179653, 6.03059170814231] | AU43: [None, 'submit_text'] | AZ43: 1.1 | BA43: 1 | BB43: 2025-11-09_11h41.23.238 | BC43: word_priming_sp | BE43: 2025.1.1 | BF43: None | BG43: 2025-11-09 11h41.40.626864 +0530
B44: 22 | C44: 22 | D44: 0 | G44: p_ _e | H44: page | I44: new | J44: pope | K44: [] | L44: [] | M44: [] | N44: [] | O44: [] | P44: [] | Q44: [] | V44: 0 | W44: 22 | X44: 22 | Y44: 21 | Z44: 171.49873 | AH44: 171.48934 | AI44: 171.49873 | AJ44: 171.49873 | AK44: 171.49873 | AL44: 0.001764833 | AM44: 181.48606 | AN44: pope | AO44: [] | AP44: [] | AQ44: [] | AR44: [] | AS44: [] | AT44: [] | AU44: [] | AV44: 181.49775 | AW44: 181.49775 | AX44: 181.49775 | AY44: 9.9982833 | AZ44: 1.1 | BA44: 1 | BB44: 2025-11-09_11h41.23.238 | BC44: word_priming_sp | BE44: 2025.1.1 | BF44: None | BG44: 2025-11-09 11h41.40.626864 +0530
B45: 23 | C45: 23 | D45: 0 | G45: a_da_i_ _s | H45: audacious | I45: old | K45: [np.float64(0.01618705035971223)] | L45: [np.float64(-0.295863309352518)] | M45: [1] | N45: [0] | O45: [0] | P45: [0.20084900013171136] | Q45: ['submit_text'] | V45: 0 | W45: 23 | X45: 23 | Y45: 12 | Z45: 181.49775 | AH45: 181.48844 | AI45: 181.49775 | AJ45: 181.49775 | AK45: 181.49775 | AL45: 0.00086479192 | AM45: 181.68951 | AO45: [np.float64(0.01618705035971223)] | AP45: [np.float64(-0.295863309352518)] | AQ45: [1] | AR45: [0] | AS45: [0] | AT45: [0.20084900013171136] | AU45: ['submit_text'] | AZ45: 1.1 | BA45: 1 | BB45: 2025-11-09_11h41.23.238 | BC45: word_priming_sp | BE45: 2025.1.1 | BF45: None | BG45: 2025-11-09 11h41.40.626864 +0530
B46: 24 | C46: 24 | D46: 0 | G46: o_sc_r_ | H46: obscure | I46: new | K46: [np.float64(-0.030575539568345324), np.float64(-0.012589928057553957), np.float64(-0.006294964028776978)] | L46: [np.float64(0.09892086330935251), np.float64(-0.329136690647482), np.float64(-0.31564748201438847)] | M46: [1, 1, 1] | N46: [0, 0, 0] | O46: [0, 0, 0] | P46: [5.613179542124271, 7.24460183409974, 8.211236542090774] | Q46: [None, None, 'submit_text'] | V46: 0 | W46: 24 | X46: 24 | Y46: 24 | Z46: 181.69935 | AH46: 181.69117 | AI46: 181.69935 | AJ46: 181.69935 | AK46: 181.69935 | AL46: 0.0015781249 | AM46: 189.9026 | AO46: [np.float64(-0.030575539568345324), np.float64(-0.012589928057553957), np.float64(-0.006294964028776978)] | AP46: [np.float64(0.09892086330935251), np.float64(-0.329136690647482), np.float64(-0.31564748201438847)] | AQ46: [1, 1, 1] | AR46: [0, 0, 0] | AS46: [0, 0, 0] | AT46: [5.613179542124271, 7.24460183409974, 8.211236542090774] | AU46: [None, None, 'submit_text'] | AZ46: 1.1 | BA46: 1 | BB46: 2025-11-09_11h41.23.238 | BC46: word_priming_sp | BE46: 2025.1.1 | BF46: None | BG46: 2025-11-09 11h41.40.626864 +0530
K48: prop hit from study list | L48: 8 by 12 | M48: =8/12 -> 0.66666667
...

Sheet 2 sleep
A1: study_word | B1: thisN | C1: thisTrialN | D1: thisRepN | E1: StudySlider.response | F1: StudySlider.rt | G1: test_word | H1: Reference | I1: old_new | J1: test_textbox.text | K1: testmouse.x | L1: testmouse.y | M1: testmouse.leftButton | N1: testmouse.midButton | O1: testmouse.rightButton | P1: testmouse.time | Q1: testmouse.clicked_name | R1: trials.thisRepN | S1: trials.thisTrialN | T1: trials.thisN | U1: trials.thisIndex | V1: trials_2.thisRepN | W1: trials_2.thisTrialN | X1: trials_2.thisN | Y1: trials_2.thisIndex | Z1: thisRow.t | AA1: notes | AB1: trial.started | AC1: StudyText.started | AD1: StudySlider.started | AE1: trial.stopped | AF1: trials.StudySlider.response | AG1: trials.StudySlider.rt | AH1: Test_Phase.started | AI1: TestText.started | AJ1: test_textbox.started | AK1: submit_text.started | AL1: testmouse.started | AM1: Test_Phase.stopped | AN1: trials_2.test_textbox.text | AO1: trials_2.testmouse.x | AP1: trials_2.testmouse.y | AQ1: trials_2.testmouse.leftButton | AR1: trials_2.testmouse.midButton | AS1: trials_2.testmouse.rightButton | AT1: trials_2.testmouse.time | AU1: trials_2.testmouse.clicked_name | AV1: participant | AW1: session | AX1: date | AY1: expName | AZ1: expVersion | BA1: psychopyVersion | BB1: frameRate | BC1: expStart
A2: minimum | B2: 0 | C2: 0 | D2: 0 | E2: 1.0431655 | F2: 1.450383 | R2: 0 | S2: 0 | T2: 0 | U2: 8 | Z2: 0.042250458 | AB2: 0.02141875 | AC2: 0.042250458 | AD2: 0.042250458 | AE2: 1.4803712 | AF2: 1.0431655 | AG2: 1.450383 | AV2: 2 | AW2: 1 | AX2: 2025-11-09_00h08.27.457 | AY2: word_priming_sp | BA2: 2025.1.1 | BB2: None | BC2: 2025-11-09 00h08.36.680229 +0530
A3: book | B3: 1 | C3: 1 | D3: 0 | E3: 1.0431655 | F3: 0.88969325 | R3: 0 | S3: 1 | T3: 1 | U3: 0 | Z3: 1.488784 | AB3: 1.4821243 | AC3: 1.488784 | AD3: 1.488784 | AE3: 2.3808749 | AF3: 1.0431655 | AG3: 0.88969325 | AV3: 2 | AW3: 1 | AX3: 2025-11-09_00h08.27.457 | AY3: word_priming_sp | BA3: 2025.1.1 | BB3: None | BC3: 2025-11-09 00h08.36.680229 +0530
A4: cruise | B4: 2 | C4: 2 | D4: 0 | E4: 1.0431655 | F4: 0.73756121 | R4: 0 | S4: 2 | T4: 2 | U4: 9 | Z4: 2.3908582 | AB4: 2.384221 | AC4: 2.3908582 | AD4: 2.3908582 | AE4: 3.1308276 | AF4: 1.0431655 | AG4: 0.73756121 | AV4: 2 | AW4: 1 | AX4: 2025-11-09_00h08.27.457 | AY4: word_priming_sp | BA4: 2025.1.1 | BB4: None | BC4: 2025-11-09 00h08.36.680229 +0530
A5: vicarious | B5: 3 | C5: 3 | D5: 0 | E5: 1.0431655 | F5: 1.037907 | R5: 0 | S5: 3 | T5: 3 | U5: 19 | Z5: 3.1403396 | AB5: 3.1338393 | AC5: 3.1403396 | AD5: 3.1403396 | AE5: 4.180823 | AF5: 1.0431655 | AG5: 1.037907 | AV5: 2 | AW5: 1 | AX5: 2025-11-09_00h08.27.457 | AY5: word_priming_sp | BA5: 2025.1.1 | BB5: None | BC5: 2025-11-09 00h08.36.680229 +0530
A6: sandwich | B6: 4 | C6: 4 | D6: 0 | E6: 1.0431655 | F6: 0.68760221 | R6: 0 | S6: 4 | T6: 4 | U6: 2 | Z6: 4.1905912 | AB6: 4.1840538 | AC6: 4.1905912 | AD6: 4.1905912 | AE6: 4.8808517 | AF6: 1.0431655 | AG6: 0.68760221 | AV6: 2 | AW6: 1 | AX6: 2025-11-09_00h08.27.457 | AY6: word_priming_sp | BA6: 2025.1.1 | BB6: None | BC6: 2025-11-09 00h08.36.680229 +0530
A7: parsimony | B7: 5 | C7: 5 | D7: 0 | E7: 1.0431655 | F7: 1.1712621 | R7: 0 | S7: 5 | T7: 5 | U7: 18 | Z7: 4.8900038 | AB7: 4.8835868 | AC7: 4.8900038 | AD7: 4.8900038 | AE7: 6.064098 | AF7: 1.0431655 | AG7: 1.1712621 | AV7: 2 | AW7: 1 | AX7: 2025-11-09_00h08.27.457 | AY7: word_priming_sp | BA7: 2025.1.1 | BB7: None | BC7: 2025-11-09 00h08.36.680229 +0530
A8: memory | B8: 6 | C8: 6 | D8: 0 | E8: 1.0431655 | F8: 0.78932237 | R8: 0 | S8: 6 | T8: 6 | U8: 3 | Z8: 6.072206 | AB8: 6.065753 | AC8: 6.072206 | AD8: 6.072206 | AE8: 6.8641457 | AF8: 1.0431655 | AG8: 0.78932237 | AV8: 2 | AW8: 1 | AX8: 2025-11-09_00h08.27.457 | AY8: word_priming_sp | BA8: 2025.1.1 | BB8: None | BC8: 2025-11-09 00h08.36.680229 +0530
A9: beguile | B9: 7 | C9: 7 | D9: 0 | E9: 1.0431655 | F9: 1.4385292 | R9: 0 | S9: 7 | T9: 7 | U9: 14 | Z9: 6.8732728 | AB9: 6.8666532 | AC9: 6.8732728 | AD9: 6.8732728 | AE9: 8.3141512 | AF9: 1.0431655 | AG9: 1.4385292 | AV9: 2 | AW9: 1 | AX9: 2025-11-09_00h08.27.457 | AY9: word_priming_sp | BA9: 2025.1.1 | BB9: None | BC9: 2025-11-09 00h08.36.680229 +0530
A10: insipid | B10: 8 | C10: 8 | D10: 0 | E10: 1.0431655 | F10: 2.4553846 | R10: 0 | S10: 8 | T10: 8 | U10: 15 | Z10: 8.322621 | AB10: 8.3160313 | AC10: 8.322621 | AD10: 8.322621 | AE10: 10.780852 | AF10: 1.0431655 | AG10: 2.4553846 | AV10: 2 | AW10: 1 | AX10: 2025-11-09_00h08.27.457 | AY10: word_priming_sp | BA10: 2025.1.1 | BB10: None | BC10: 2025-11-09 00h08.36.680229 +0530
A11: booth | B11: 9 | C11: 9 | D11: 0 | E11: 1.0431655 | F11: 0.62231408 | R11: 0 | S11: 9 | T11: 9 | U11: 5 | Z11: 10.789474 | AB11: 10.782848 | AC11: 10.789474 | AD11: 10.789474 | AE11: 11.414102 | AF11: 1.0431655 | AG11: 0.62231408 | AV11: 2 | AW11: 1 | AX11: 2025-11-09_00h08.27.457 | AY11: word_priming_sp | BA11: 2025.1.1 | BB11: None | BC11: 2025-11-09 00h08.36.680229 +0530
A12: carpet | B12: 10 | C12: 10 | D12: 0 | E12: 1.0431655 | F12: 0.50585683 | R12: 0 | S12: 10 | T12: 10 | U12: 1 | Z12: 11.422569 | AB12: 11.415954 | AC12: 11.422569 | AD12: 11.422569 | AE12: 11.930801 | AF12: 1.0431655 | AG12: 0.50585683 | AV12: 2 | AW12: 1 | AX12: 2025-11-09_00h08.27.457 | AY12: word_priming_sp | BA12: 2025.1.1 | BB12: None | BC12: 2025-11-09 00h08.36.680229 +0530
A13: audacious | B13: 11 | C13: 11 | D13: 0 | E13: 3.0431655 | F13: 1.8890095 | R13: 0 | S13: 11 | T13: 11 | U13: 12 | Z13: 11.93931 | AB13: 11.932635 | AC13: 11.93931 | AD13: 11.93931 | AE13: 13.830747 | AF13: 3.0431655 | AG13: 1.8890095 | AV13: 2 | AW13: 1 | AX13: 2025-11-09_00h08.27.457 | AY13: word_priming_sp | BA13: 2025.1.1 | BB13: None | BC13: 2025-11-09 00h08.36.680229 +0530
... A21: hose | B21: 19 | C21: 19 | D21: 0 | E21: 1 | F21: 0.47281179 | R21: 0 | S21: 19 | T21: 19 | U21: 4 | Z21: 20.739136 | AB21: 20.732366 | AC21: 20.739136 | AD21: 20.739136 | AE21: 21.213536 | AF21: 1 | AG21: 0.47281179 | AV21: 2 | AW21: 1 | AX21: 2025-11-09_00h08.27.457 | AY21: word_priming_sp | BA21: 2025.1.1 | BB21: None | BC21: 2025-11-09 00h08.36.680229 +0530
B22: 0 | C22: 0 | D22: 0 | G22: p_ _e | H22: page | I22: new | J22: pose | K22: [np.float64(0.03866906474820144)] | L22: [np.float64(-0.30845323741007197)] | M22: [1] | N22: [0] | O22: [0] | P22: [4.266983499983326] | Q22: ['submit_text'] | V22: 0 | W22: 0 | X22: 0 | Y22: 21 | Z22: 21.231086 | AH22: 21.222204 | AI22: 21.231086 | AJ22: 21.231086 | AK22: 21.231086 | AL22: 0.0086682911 | AM22: 25.489344 | AN22: pose | AO22: [np.float64(0.03866906474820144)] | AP22: [np.float64(-0.30845323741007197)] | AQ22: [1] | AR22: [0] | AS22: [0] | AT22: [4.266983499983326] | AU22: ['submit_text'] | AV22: 2 | AW22: 1 | AX22: 2025-11-09_00h08.27.457 | AY22: word_priming_sp | BA22: 2025.1.1 | BB22: None | BC22: 2025-11-09 00h08.36.680229 +0530
B23: 1 | C23: 1 | D23: 0 | G23: pa_s_m_ _y | H23: parsimony | I23: old | J23: parsimony | K23: [np.float64(0.03866906474820144)] | L23: [np.float64(-0.30845323741007197)] | M23: [1] | N23: [0] | O23: [0] | P23: [5.780695124994963] | Q23: ['submit_text'] | V23: 0 | W23: 1 | X23: 1 | Y23: 18 | Z23: 25.50034 | AH23: 25.492183 | AI23: 25.50034 | AJ23: 25.50034 | AK23: 25.50034 | AL23: 0.002661875 | AM23: 31.273077 | AN23: parsimony | AO23: [np.float64(0.03866906474820144)] | AP23: [np.float64(-0.30845323741007197)] | AQ23: [1] | AR23: [0] | AS23: [0] | AT23: [5.780695124994963] | AU23: ['submit_text'] | AV23: 2 | AW23: 1 | AX23: 2025-11-09_00h08.27.457 | AY23: word_priming_sp | BA23: 2025.1.1 | BB23: None | BC23: 2025-11-09 00h08.36.680229 +0530
B24: 2 | C24: 2 | D24: 0 | G24: b_gu_l_ | H24: beguile | I24: old | J24: beguile | K24: [np.float64(0.0368705035971223)] | L24: [np.float64(-0.30845323741007197)] | M24: [1] | N24: [0] | O24: [0] | P24: [2.8975059590302408] | Q24: ['submit_text'] | V24: 0 | W24: 2 | X24: 2 | Y24: 14 | Z24: 31.284249 | AH24: 31.275097 | AI24: 31.284249 | AJ24: 31.284249 | AK24: 31.284249 | AL24: 0.0019247502 | AM24: 34.172802 | AN24: beguile | AO24: [np.float64(0.0368705035971223)] | AP24: [np.float64(-0.30845323741007197)] | AQ24: [1] | AR24: [0] | AS24: [0] | AT24: [2.8975059590302408] | AU24: ['submit_text'] | AV24: 2 | AW24: 1 | AX24: 2025-11-09_00h08.27.457 | AY24: word_priming_sp | BA24: 2025.1.1 | BB24: None | BC24: 2025-11-09 00h08.36.680229 +0530
B25: 3 | C25: 3 | D25: 0 | G25: _os_ | H25: hose | I25: old | J25: hose | K25: [np.float64(0.0368705035971223)] | L25: [np.float64(-0.30845323741007197)] | M25: [1] | N25: [0] | O25: [0] | P25: [2.747535000089556] | Q25: ['submit_text'] | V25: 0 | W25: 3 | X25: 3 | Y25: 4 | Z25: 34.184195 | AH25: 34.174576 | AI25: 34.184195 | AJ25: 34.184195 | AK25: 34.184195 | AL25: 0.001681292 | AM25: 36.922296 | AN25: hose | AO25: [np.float64(0.0368705035971223)] | AP25: [np.float64(-0.30845323741007197)] | AQ25: [1] | AR25: [0] | AS25: [0] | AT25: [2.747535000089556] | AU25: ['submit_text'] | AV25: 2 | AW25: 1 | AX25: 2025-11-09_00h08.27.457 | AY25: word_priming_sp | BA25: 2025.1.1 | BB25: None | BC25: 2025-11-09 00h08.36.680229 +0530
B26: 4 | C26: 4 | D26: 0 | G26: c_ _hi_n | H26: cushion | I26: new | J26: cushion | K26: [np.float64(0.0368705035971223)] | L26: [np.float64(-0.30845323741007197)] | M26: [1] | N26: [0] | O26: [0] | P26: [1.8804919579997659] | Q26: ['submit_text'] | V26: 0 | W26: 4 | X26: 4 | Y26: 20 | Z26: 36.934215 | AH26: 36.924681 | AI26: 36.934215 | AJ26: 36.934215 | AK26: 36.934215 | AL26: 0.0022744169 | AM26: 38.805376 | AN26: cushion | AO26: [np.float64(0.0368705035971223)] | AP26: [np.float64(-0.30845323741007197)] | AQ26: [1] | AR26: [0] | AS26: [0] | AT26: [1.8804919579997659] | AU26: ['submit_text'] | AV26: 2 | AW26: 1 | AX26: 2025-11-09_00h08.27.457 | AY26: word_priming_sp | BA26: 2025.1.1 | BB26: None | BC26: 2025-11-09 00h08.36.680229 +0530
B27: 5 | C27: 5 | D27: 0 | G27: la_g_ _e_ | H27: laughter | I27: old | J27: laughter | K27: [np.float64(0.0368705035971223)] | L27: [np.float64(-0.30845323741007197)] | M27: [1] | N27: [0] | O27: [0] | P27: [1.7485507081728429] | Q27: ['submit_text'] | V27: 0 | W27: 5 | X27: 5 | Y27: 6 | Z27: 38.817035 | AH27: 38.807708 | AI27: 38.817035 | AJ27: 38.817035 | AK27: 38.817035 | AL27: 0.0022356249 | AM27: 40.556484 | AN27: laughter | AO27: [np.float64(0.0368705035971223)] | AP27: [np.float64(-0.30845323741007197)] | AQ27: [1] | AR27: [0] | AS27: [0] | AT27: [1.7485507081728429] | AU27: ['submit_text'] | AV27: 2 | AW27: 1 | AX27: 2025-11-09_00h08.27.457 | AY27: word_priming_sp | BA27: 2025.1.1 | BB27: None | BC27: 2025-11-09 00h08.36.680229 +0530
